2020-10-09 13:34:30,016 - INFO - RabbitMq thread started app starting
2020-10-09 13:34:30,021 - INFO - Pika version 1.1.0 connecting to ('172.21.0.5', 5672)
2020-10-09 13:34:30,030 - INFO -  * Running on http://0.0.0.0:4500/ (Press CTRL+C to quit)
2020-10-09 13:34:30,039 - ERROR - Socket failed to connect: <socket.socket fd=9, family=AddressFamily.AF_INET, type=2049, proto=6, laddr=('172.21.0.8', 33252)>; error=111 (Connection refused)
2020-10-09 13:34:30,046 - ERROR - TCP Connection attempt failed: ConnectionRefusedError(111, 'Connection refused'); dest=(<AddressFamily.AF_INET: 2>, <SocketKind.SOCK_STREAM: 1>, 6, '', ('172.21.0.5', 5672))
2020-10-09 13:34:30,048 - ERROR - AMQPConnector - reporting failure: AMQPConnectorSocketConnectError: ConnectionRefusedError(111, 'Connection refused')
2020-10-09 13:34:30,053 - ERROR - AMQP connection workflow failed: AMQPConnectionWorkflowFailed: 1 exceptions in all; last exception - AMQPConnectorSocketConnectError: ConnectionRefusedError(111, 'Connection refused'); first exception - None.
2020-10-09 13:34:30,058 - ERROR - AMQPConnectionWorkflow - reporting failure: AMQPConnectionWorkflowFailed: 1 exceptions in all; last exception - AMQPConnectorSocketConnectError: ConnectionRefusedError(111, 'Connection refused'); first exception - None
2020-10-09 13:34:30,059 - ERROR - Connection workflow failed: AMQPConnectionWorkflowFailed: 1 exceptions in all; last exception - AMQPConnectorSocketConnectError: ConnectionRefusedError(111, 'Connection refused'); first exception - None
2020-10-09 13:34:30,065 - ERROR - Error in _create_connection().
Traceback (most recent call last):
  File "/usr/local/lib/python3.6/site-packages/pika/adapters/blocking_connection.py", line 450, in _create_connection
    raise self._reap_last_connection_workflow_error(error)
pika.exceptions.AMQPConnectionError
2020-10-09 13:36:17,266 - INFO - ClientHistory API
2020-10-09 13:36:17,548 - INFO - MongoDB - Got client History
2020-10-09 13:36:17,550 - INFO - MongoDb - Got client History
2020-10-09 13:36:17,625 - INFO - 172.21.0.1 - - [09/Oct/2020 13:36:17] "[37mGET /client/history/5 HTTP/1.1[0m" 200 -
2020-10-09 13:36:24,197 - INFO - fileUpload API
2020-10-09 13:36:26,639 - INFO - AWS S3 - Upload successful
2020-10-09 13:36:26,642 - INFO - {'clientName': ['Jon Doe'], 'clientId': ['5'], 'activity': ['1'], 'fileId': ['12'], 'fileName': 'weights/questions.pdf', 'url': 'https://s3.amazonaws.com/weightsbucket/weights/questions.pdf'}
2020-10-09 13:36:26,669 - INFO - MongoDB - Inserted to the MongoDB
2020-10-09 13:36:26,671 - INFO - 172.21.0.1 - - [09/Oct/2020 13:36:26] "[37mPOST /file/upload HTTP/1.1[0m" 200 -
2020-10-09 13:36:29,849 - INFO - ClientHistory API
2020-10-09 13:36:29,870 - INFO - MongoDB - Got client History
2020-10-09 13:36:29,872 - INFO - MongoDb - Got client History
2020-10-09 13:36:29,875 - INFO - 172.21.0.1 - - [09/Oct/2020 13:36:29] "[37mGET /client/history/5 HTTP/1.1[0m" 200 -
2020-10-09 13:42:44,805 - INFO - RabbitMq thread started app starting
2020-10-09 13:42:44,826 - INFO - Pika version 1.1.0 connecting to ('172.21.0.2', 5672)
2020-10-09 13:42:44,830 - ERROR - Socket failed to connect: <socket.socket fd=9, family=AddressFamily.AF_INET, type=2049, proto=6, laddr=('172.21.0.7', 33134)>; error=111 (Connection refused)
2020-10-09 13:42:44,851 - ERROR - TCP Connection attempt failed: ConnectionRefusedError(111, 'Connection refused'); dest=(<AddressFamily.AF_INET: 2>, <SocketKind.SOCK_STREAM: 1>, 6, '', ('172.21.0.2', 5672))
2020-10-09 13:42:44,845 - INFO -  * Running on http://0.0.0.0:4500/ (Press CTRL+C to quit)
2020-10-09 13:42:44,854 - ERROR - AMQPConnector - reporting failure: AMQPConnectorSocketConnectError: ConnectionRefusedError(111, 'Connection refused')
2020-10-09 13:42:44,857 - ERROR - AMQP connection workflow failed: AMQPConnectionWorkflowFailed: 1 exceptions in all; last exception - AMQPConnectorSocketConnectError: ConnectionRefusedError(111, 'Connection refused'); first exception - None.
2020-10-09 13:42:44,860 - ERROR - AMQPConnectionWorkflow - reporting failure: AMQPConnectionWorkflowFailed: 1 exceptions in all; last exception - AMQPConnectorSocketConnectError: ConnectionRefusedError(111, 'Connection refused'); first exception - None
2020-10-09 13:42:44,862 - ERROR - Connection workflow failed: AMQPConnectionWorkflowFailed: 1 exceptions in all; last exception - AMQPConnectorSocketConnectError: ConnectionRefusedError(111, 'Connection refused'); first exception - None
2020-10-09 13:42:44,865 - ERROR - Error in _create_connection().
Traceback (most recent call last):
  File "/usr/local/lib/python3.6/site-packages/pika/adapters/blocking_connection.py", line 450, in _create_connection
    raise self._reap_last_connection_workflow_error(error)
pika.exceptions.AMQPConnectionError
2020-10-10 11:28:04,189 - INFO - RabbitMq thread started app starting
2020-10-10 11:28:04,206 - INFO -  * Running on http://0.0.0.0:4500/ (Press CTRL+C to quit)
2020-10-10 11:28:04,218 - INFO - Pika version 1.1.0 connecting to ('172.18.0.5', 5672)
2020-10-10 11:28:04,555 - INFO - Socket connected: <socket.socket fd=9, family=AddressFamily.AF_INET, type=2049, proto=6, laddr=('172.18.0.14', 60798), raddr=('172.18.0.5', 5672)>
2020-10-10 11:28:04,683 - INFO - Streaming transport linked up: (<pika.adapters.utils.io_services_utils._AsyncPlaintextTransport object at 0x7f7144d28828>, _StreamingProtocolShim: <SelectConnection PROTOCOL transport=<pika.adapters.utils.io_services_utils._AsyncPlaintextTransport object at 0x7f7144d28828> params=<ConnectionParameters host=rabbitmq port=5672 virtual_host=/ ssl=False>>).
2020-10-10 11:28:04,874 - INFO - AMQPConnector - reporting success: <SelectConnection OPEN transport=<pika.adapters.utils.io_services_utils._AsyncPlaintextTransport object at 0x7f7144d28828> params=<ConnectionParameters host=rabbitmq port=5672 virtual_host=/ ssl=False>>
2020-10-10 11:28:04,922 - INFO - AMQPConnectionWorkflow - reporting success: <SelectConnection OPEN transport=<pika.adapters.utils.io_services_utils._AsyncPlaintextTransport object at 0x7f7144d28828> params=<ConnectionParameters host=rabbitmq port=5672 virtual_host=/ ssl=False>>
2020-10-10 11:28:05,102 - INFO - Connection workflow succeeded: <SelectConnection OPEN transport=<pika.adapters.utils.io_services_utils._AsyncPlaintextTransport object at 0x7f7144d28828> params=<ConnectionParameters host=rabbitmq port=5672 virtual_host=/ ssl=False>>
2020-10-10 11:28:05,294 - INFO - Created channel=1
2020-10-10 11:28:10,404 - INFO - AWS S3 - Upload successful
2020-10-10 11:28:10,405 - INFO - {'clientName': "<FileStorage: 'user_name' (None)>", 'clientId': "<FileStorage: 'user_id' (None)>", 'filename': '692d5548-6b4c-478e-bb64-55357443d28a', 'activity': 1, 'created': datetime.datetime(2020, 10, 10, 11, 28, 10, 405406), 'url': 'https://s3.amazonaws.com/weightsbucket/weights/692d5548-6b4c-478e-bb64-55357443d28a'}
2020-10-10 11:28:10,953 - INFO - MongoDB - Inserted to the MongoDB
2020-10-10 11:28:11,073 - INFO - File Uploaded Successfully
2020-10-10 11:28:11,106 - ERROR - AWS S3- Upload fail
2020-10-10 11:32:11,725 - INFO - RabbitMq thread started app starting
2020-10-10 11:32:11,734 - INFO -  * Running on http://0.0.0.0:4500/ (Press CTRL+C to quit)
2020-10-10 11:32:12,760 - ERROR - Address resolution failed: gaierror(-5, 'No address associated with hostname')
2020-10-10 11:32:12,762 - ERROR - getaddrinfo failed: gaierror(-5, 'No address associated with hostname').
2020-10-10 11:32:12,763 - ERROR - AMQP connection workflow failed: AMQPConnectionWorkflowFailed: 1 exceptions in all; last exception - gaierror(-5, 'No address associated with hostname'); first exception - None.
2020-10-10 11:32:12,774 - ERROR - AMQPConnectionWorkflow - reporting failure: AMQPConnectionWorkflowFailed: 1 exceptions in all; last exception - gaierror(-5, 'No address associated with hostname'); first exception - None
2020-10-10 11:32:12,780 - ERROR - Connection workflow failed: AMQPConnectionWorkflowFailed: 1 exceptions in all; last exception - gaierror(-5, 'No address associated with hostname'); first exception - None
2020-10-10 11:32:12,796 - ERROR - Error in _create_connection().
Traceback (most recent call last):
  File "/usr/local/lib/python3.6/site-packages/pika/adapters/blocking_connection.py", line 450, in _create_connection
    raise self._reap_last_connection_workflow_error(error)
  File "/usr/local/lib/python3.6/site-packages/pika/adapters/utils/selector_ioloop_adapter.py", line 564, in _resolve
    self._flags)
  File "/usr/local/lib/python3.6/socket.py", line 745, in getaddrinfo
    for res in _socket.getaddrinfo(host, port, family, type, proto, flags):
socket.gaierror: [Errno -5] No address associated with hostname
2020-10-10 11:34:27,188 - INFO - RabbitMq thread started app starting
2020-10-10 11:34:27,193 - INFO - Pika version 1.1.0 connecting to ('172.19.0.4', 5672)
2020-10-10 11:34:27,256 - ERROR - Socket failed to connect: <socket.socket fd=9, family=AddressFamily.AF_INET, type=2049, proto=6, laddr=('172.19.0.14', 52804)>; error=111 (Connection refused)
2020-10-10 11:34:27,260 - INFO -  * Running on http://0.0.0.0:4500/ (Press CTRL+C to quit)
2020-10-10 11:34:27,260 - ERROR - TCP Connection attempt failed: ConnectionRefusedError(111, 'Connection refused'); dest=(<AddressFamily.AF_INET: 2>, <SocketKind.SOCK_STREAM: 1>, 6, '', ('172.19.0.4', 5672))
2020-10-10 11:34:27,297 - ERROR - AMQPConnector - reporting failure: AMQPConnectorSocketConnectError: ConnectionRefusedError(111, 'Connection refused')
2020-10-10 11:34:27,362 - ERROR - AMQP connection workflow failed: AMQPConnectionWorkflowFailed: 1 exceptions in all; last exception - AMQPConnectorSocketConnectError: ConnectionRefusedError(111, 'Connection refused'); first exception - None.
2020-10-10 11:34:27,410 - ERROR - AMQPConnectionWorkflow - reporting failure: AMQPConnectionWorkflowFailed: 1 exceptions in all; last exception - AMQPConnectorSocketConnectError: ConnectionRefusedError(111, 'Connection refused'); first exception - None
