2020-10-12 14:33:19,884 - ERROR - Connection workflow failed: AMQPConnectionWorkflowFailed: 1 exceptions in all; last exception - AMQPConnectorSocketConnectError: ConnectionRefusedError(111, 'Connection refused'); first exception - None
2020-10-12 14:33:19,912 - ERROR - Error in _create_connection().
Traceback (most recent call last):
  File "/usr/local/lib/python3.6/site-packages/pika/adapters/blocking_connection.py", line 450, in _create_connection
    raise self._reap_last_connection_workflow_error(error)
pika.exceptions.AMQPConnectionError
2020-10-12 14:45:13,272 - INFO - RabbitMq thread started app starting
2020-10-12 14:45:13,277 - INFO - Pika version 1.1.0 connecting to ('172.21.0.7', 5672)
2020-10-12 14:45:13,279 - ERROR - Socket failed to connect: <socket.socket fd=9, family=AddressFamily.AF_INET, type=2049, proto=6, laddr=('172.21.0.12', 53858)>; error=111 (Connection refused)
2020-10-12 14:45:13,281 - ERROR - TCP Connection attempt failed: ConnectionRefusedError(111, 'Connection refused'); dest=(<AddressFamily.AF_INET: 2>, <SocketKind.SOCK_STREAM: 1>, 6, '', ('172.21.0.7', 5672))
2020-10-12 14:45:13,284 - ERROR - AMQPConnector - reporting failure: AMQPConnectorSocketConnectError: ConnectionRefusedError(111, 'Connection refused')
2020-10-12 14:45:13,287 - ERROR - AMQP connection workflow failed: AMQPConnectionWorkflowFailed: 1 exceptions in all; last exception - AMQPConnectorSocketConnectError: ConnectionRefusedError(111, 'Connection refused'); first exception - None.
2020-10-12 14:45:13,289 - ERROR - AMQPConnectionWorkflow - reporting failure: AMQPConnectionWorkflowFailed: 1 exceptions in all; last exception - AMQPConnectorSocketConnectError: ConnectionRefusedError(111, 'Connection refused'); first exception - None
2020-10-12 14:45:13,278 - INFO -  * Running on http://0.0.0.0:4500/ (Press CTRL+C to quit)
2020-10-12 14:45:13,291 - ERROR - Connection workflow failed: AMQPConnectionWorkflowFailed: 1 exceptions in all; last exception - AMQPConnectorSocketConnectError: ConnectionRefusedError(111, 'Connection refused'); first exception - None
2020-10-12 14:45:13,294 - ERROR - Error in _create_connection().
Traceback (most recent call last):
  File "/usr/local/lib/python3.6/site-packages/pika/adapters/blocking_connection.py", line 450, in _create_connection
    raise self._reap_last_connection_workflow_error(error)
pika.exceptions.AMQPConnectionError
